2025-05-22 19:00:41 - movie_recommender - INFO - Starting training pipeline
2025-05-22 19:00:41 - movie_recommender - INFO - Configuration: {'data': {'test_size': 0.2, 'random_state': 42, 'validation_size': 0.1}, 'model': {'neural_network': {'architecture': [64, 32, 16], 'activation': 'relu', 'dropout_rate': 0.2, 'learning_rate': 0.001, 'batch_size': 64, 'epochs': 100, 'early_stopping_patience': 10}, 'fuzzy_system': {'membership_functions': 3, 'defuzzification_method': 'centroid', 'inference_method': 'mamdani'}}, 'training': {'optimizer': 'adam', 'loss': 'mean_squared_error', 'metrics': ['mae', 'rmse']}, 'evaluation': {'metrics': ['precision', 'recall', 'f1', 'ndcg', 'map'], 'k_values': [5, 10, 20]}}
2025-05-22 19:00:41 - movie_recommender - INFO - Attempting to load merged data...
2025-05-22 19:00:41 - movie_recommender.pipelines.train_pipeline_fixed - INFO - Starting load_merged_data
2025-05-22 19:00:41 - movie_recommender.pipeline - INFO - Loading merged data from D:\college\computer science level 3\second term\soft computing\soft_computing_project\Movie_recomendation_system\neuro-fuzzy-model\data\processed
2025-05-22 19:01:05 - movie_recommender - ERROR - Error in training pipeline: realloc of size 33554432 failed
Traceback (most recent call last):
  File "d:\college\computer science level 3\second term\soft computing\soft_computing_project\Movie_recomendation_system\neuro-fuzzy-model\pipelines\train_pipeline_fixed.py", line 201, in main
    movie_features, user_features, ratings_df = load_merged_data(features_dir)
                                                ^^^^^^^^^^^^^^^^^^^^^^^^^^^^^^
  File "d:\college\computer science level 3\second term\soft computing\soft_computing_project\Movie_recomendation_system\neuro-fuzzy-model\src\movie_recommender\utils\logging.py", line 97, in wrapper
    result = func(*args, **kwargs)
             ^^^^^^^^^^^^^^^^^^^^^
  File "d:\college\computer science level 3\second term\soft computing\soft_computing_project\Movie_recomendation_system\neuro-fuzzy-model\pipelines\train_pipeline_fixed.py", line 127, in load_merged_data
    merged_df = pd.read_parquet(merged_data_path)
                ^^^^^^^^^^^^^^^^^^^^^^^^^^^^^^^^^
  File "C:\Python312\Lib\site-packages\pandas\io\parquet.py", line 667, in read_parquet
    return impl.read(
           ^^^^^^^^^^
  File "C:\Python312\Lib\site-packages\pandas\io\parquet.py", line 274, in read
    pa_table = self.api.parquet.read_table(
               ^^^^^^^^^^^^^^^^^^^^^^^^^^^^
  File "C:\Python312\Lib\site-packages\pyarrow\parquet\core.py", line 1824, in read_table
    return dataset.read(columns=columns, use_threads=use_threads,
           ^^^^^^^^^^^^^^^^^^^^^^^^^^^^^^^^^^^^^^^^^^^^^^^^^^^^^^
  File "C:\Python312\Lib\site-packages\pyarrow\parquet\core.py", line 1475, in read
    table = self._dataset.to_table(
            ^^^^^^^^^^^^^^^^^^^^^^^
  File "pyarrow\\_dataset.pyx", line 589, in pyarrow._dataset.Dataset.to_table
  File "pyarrow\\_dataset.pyx", line 3941, in pyarrow._dataset.Scanner.to_table
  File "pyarrow\\error.pxi", line 155, in pyarrow.lib.pyarrow_internal_check_status
  File "pyarrow\\error.pxi", line 92, in pyarrow.lib.check_status
pyarrow.lib.ArrowMemoryError: realloc of size 33554432 failed
